s: 10] [MainRec: Lucidworks B2B Clients.pptx] [OtherSrc: 5] [Answer: 'I don't have enough information to provide a B2C case study from the context provided. The context f...']
2025-04-25 23:59:23,280 [INFO] [api_chat:790] Request processed in 2.54s.
2025-04-25 23:59:23,280 [DEBUG] [api_chat:791] --> Returning Response: answer_html='I don&#x27;t have enough information to provide a B2C case study from the context provided. The context focuses on B2B clients and case studies....', main_recommendation={'filename': 'Lucidworks B2B Clients.pptx',
 'link': 'https://storage.googleapis.com/lwdocbot/Seismic%20Mirror/Customer%20Stories%20%28Sommer%29/Case%20Studies/Lucidworks%20B2B%20Clients.pptx?X-Goog-Algorithm=GOOG4-RSA-SHA256&X-Goog-Credential=pipeline-sa%40elevado.iam.gserviceaccount.com%2F20250425%2Fauto%2Fstorage%2Fgoog4_request&X-Goog-Date=20250425T235923Z&X-Goog-Expires=900&X-Goog-SignedHeaders=host&X-Goog-Signature=df3ffb52ed09323f5e5cf0554c80e5f9eda9848f819535ca117728c8f603b2d36a765bfd2347f2ad4b0db1ce7b476524bf9824cb642845efa66f89f8608ee9d0e5acd129e0f55afaeb6202d5da6b8a0152cca3ce21921e0c1f20062bdeafa9af38379ccdec8179a0d5bab76a13e3be06b34e5b32ddbb9a62eaeae431cda83b611622a0eec742d013b9776797f83055999e7986ee64fe687a99da1a62d958c02512bf419ba13c4092ffde420b48a3e75acfcc8b10660cd6a3c0f392ddef7a930a5ac66d32c4ffbe05786c382af2e7175ff806f6fd6fe07d2e8e390a2c66aeb4f8126fc87bf395cc410f0eaabd74fb11d8cca490e119966bf5e7249b0e8d19d604',
 'preview_info': 'Lucidworks B2B Clients...'}, other_sources_count=5
2025-04-26 00:00:55,863 [ERROR] [finalize_request:911] Request finalizing failed with an error while handling an error
Traceback (most recent call last):
  File "/home/runner/workspace/.pythonlibs/lib/python3.11/site-packages/redis/connection.py", line 357, in connect
    sock = self.retry.call_with_retry(
           ^^^^^^^^^^^^^^^^^^^^^^^^^^^
  File "/home/runner/workspace/.pythonlibs/lib/python3.11/site-packages/redis/retry.py", line 67, in call_with_retry
    raise error
  File "/home/runner/workspace/.pythonlibs/lib/python3.11/site-packages/redis/retry.py", line 62, in call_with_retry
    return do()
           ^^^^
  File "/home/runner/workspace/.pythonlibs/lib/python3.11/site-packages/redis/connection.py", line 358, in <lambda>
    lambda: self._connect(), lambda error: self.disconnect(error)
            ^^^^^^^^^^^^^^^
  File "/home/runner/workspace/.pythonlibs/lib/python3.11/site-packages/redis/connection.py", line 730, in _connect
    raise err
  File "/home/runner/workspace/.pythonlibs/lib/python3.11/site-packages/redis/connection.py", line 718, in _connect
    sock.connect(socket_address)
TimeoutError: [Errno 110] Connection timed out

During handling of the above exception, another exception occurred:

Traceback (most recent call last):
  File "/home/runner/workspace/.pythonlibs/lib/python3.11/site-packages/flask/app.py", line 1473, in wsgi_app
    response = self.full_dispatch_request()
               ^^^^^^^^^^^^^^^^^^^^^^^^^^^^
  File "/home/runner/workspace/.pythonlibs/lib/python3.11/site-packages/flask/app.py", line 883, in full_dispatch_request
    return self.finalize_request(rv)
           ^^^^^^^^^^^^^^^^^^^^^^^^^
  File "/home/runner/workspace/.pythonlibs/lib/python3.11/site-packages/flask/app.py", line 904, in finalize_request
    response = self.process_response(response)
               ^^^^^^^^^^^^^^^^^^^^^^^^^^^^^^^
  File "/home/runner/workspace/.pythonlibs/lib/python3.11/site-packages/flask/app.py", line 1284, in process_response
    self.session_interface.save_session(self, ctx.session, response)
  File "/home/runner/workspace/.pythonlibs/lib/python3.11/site-packages/flask_session/base.py", line 305, in save_session
    self._upsert_session(app.permanent_session_lifetime, session, store_id)
  File "/home/runner/workspace/.pythonlibs/lib/python3.11/site-packages/flask_session/redis/redis.py", line 81, in _upsert_session
    self.client.set(
  File "/home/runner/workspace/.pythonlibs/lib/python3.11/site-packages/redis/commands/core.py", line 2335, in set
    return self.execute_command("SET", *pieces, **options)
           ^^^^^^^^^^^^^^^^^^^^^^^^^^^^^^^^^^^^^^^^^^^^^^^
  File "/home/runner/workspace/.pythonlibs/lib/python3.11/site-packages/redis/client.py", line 559, in execute_command
    return self._execute_command(*args, **options)
           ^^^^^^^^^^^^^^^^^^^^^^^^^^^^^^^^^^^^^^^
  File "/home/runner/workspace/.pythonlibs/lib/python3.11/site-packages/redis/client.py", line 565, in _execute_command
    conn = self.connection or pool.get_connection(command_name, **options)
                              ^^^^^^^^^^^^^^^^^^^^^^^^^^^^^^^^^^^^^^^^^^^^
  File "/home/runner/workspace/.pythonlibs/lib/python3.11/site-packages/redis/connection.py", line 1422, in get_connection
    connection.connect()
  File "/home/runner/workspace/.pythonlibs/lib/python3.11/site-packages/redis/connection.py", line 361, in connect
    raise TimeoutError("Timeout connecting to server")
redis.exceptions.TimeoutError: Timeout connecting to server

During handling of the above exception, another exception occurred:

Traceback (most recent call last):
  File "/home/runner/workspace/.pythonlibs/lib/python3.11/site-packages/redis/connection.py", line 357, in connect
    sock = self.retry.call_with_retry(
           ^^^^^^^^^^^^^^^^^^^^^^^^^^^
  File "/home/runner/workspace/.pythonlibs/lib/python3.11/site-packages/redis/retry.py", line 67, in call_with_retry
    raise error
  File "/home/runner/workspace/.pythonlibs/lib/python3.11/site-packages/redis/retry.py", line 62, in call_with_retry
    return do()
           ^^^^
  File "/home/runner/workspace/.pythonlibs/lib/python3.11/site-packages/redis/connection.py", line 358, in <lambda>
    lambda: self._connect(), lambda error: self.disconnect(error)
            ^^^^^^^^^^^^^^^
  File "/home/runner/workspace/.pythonlibs/lib/python3.11/site-packages/redis/connection.py", line 730, in _connect
    raise err
  File "/home/runner/workspace/.pythonlibs/lib/python3.11/site-packages/redis/connection.py", line 718, in _connect
    sock.connect(socket_address)
TimeoutError: [Errno 110] Connection timed out

During handling of the above exception, another exception occurred:

Traceback (most recent call last):
  File "/home/runner/workspace/.pythonlibs/lib/python3.11/site-packages/flask/app.py", line 904, in finalize_request
    response = self.process_response(response)
               ^^^^^^^^^^^^^^^^^^^^^^^^^^^^^^^
  File "/home/runner/workspace/.pythonlibs/lib/python3.11/site-packages/flask/app.py", line 1284, in process_response
    self.session_interface.save_session(self, ctx.session, response)
  File "/home/runner/workspace/.pythonlibs/lib/python3.11/site-packages/flask_session/base.py", line 305, in save_session
    self._upsert_session(app.permanent_session_lifetime, session, store_id)
  File "/home/runner/workspace/.pythonlibs/lib/python3.11/site-packages/flask_session/redis/redis.py", line 81, in _upsert_session
    self.client.set(
  File "/home/runner/workspace/.pythonlibs/lib/python3.11/site-packages/redis/commands/core.py", line 2335, in set
    return self.execute_command("SET", *pieces, **options)
           ^^^^^^^^^^^^^^^^^^^^^^^^^^^^^^^^^^^^^^^^^^^^^^^
  File "/home/runner/workspace/.pythonlibs/lib/python3.11/site-packages/redis/client.py", line 559, in execute_command
    return self._execute_command(*args, **options)
           ^^^^^^^^^^^^^^^^^^^^^^^^^^^^^^^^^^^^^^^
  File "/home/runner/workspace/.pythonlibs/lib/python3.11/site-packages/redis/client.py", line 565, in _execute_command
    conn = self.connection or pool.get_connection(command_name, **options)
                              ^^^^^^^^^^^^^^^^^^^^^^^^^^^^^^^^^^^^^^^^^^^^
  File "/home/runner/workspace/.pythonlibs/lib/python3.11/site-packages/redis/connection.py", line 1422, in get_connection
    connection.connect()
  File "/home/runner/workspace/.pythonlibs/lib/python3.11/site-packages/redis/connection.py", line 361, in connect
    raise TimeoutError("Timeout connecting to server")
redis.exceptions.TimeoutError: Timeout connecting to server
2025-04-26 00:01:32,726 [ERROR] [log_exception:838] Exception on /api/chat [POST]
Traceback (most recent call last):
  File "/home/runner/workspace/.pythonlibs/lib/python3.11/site-packages/redis/connection.py", line 357, in connect
    sock = self.retry.call_with_retry(
           ^^^^^^^^^^^^^^^^^^^^^^^^^^^
  File "/home/runner/workspace/.pythonlibs/lib/python3.11/site-packages/redis/retry.py", line 67, in call_with_retry
    raise error
  File "/home/runner/workspace/.pythonlibs/lib/python3.11/site-packages/redis/retry.py", line 62, in call_with_retry
    return do()
           ^^^^
  File "/home/runner/workspace/.pythonlibs/lib/python3.11/site-packages/redis/connection.py", line 358, in <lambda>
    lambda: self._connect(), lambda error: self.disconnect(error)
            ^^^^^^^^^^^^^^^
  File "/home/runner/workspace/.pythonlibs/lib/python3.11/site-packages/redis/connection.py", line 730, in _connect
    raise err
  File "/home/runner/workspace/.pythonlibs/lib/python3.11/site-packages/redis/connection.py", line 718, in _connect
    sock.connect(socket_address)
TimeoutError: [Errno 110] Connection timed out

During handling of the above exception, another exception occurred:

Traceback (most recent call last):
  File "/home/runner/workspace/.pythonlibs/lib/python3.11/site-packages/flask/app.py", line 1473, in wsgi_app
    response = self.full_dispatch_request()
               ^^^^^^^^^^^^^^^^^^^^^^^^^^^^
  File "/home/runner/workspace/.pythonlibs/lib/python3.11/site-packages/flask/app.py", line 883, in full_dispatch_request
    return self.finalize_request(rv)
           ^^^^^^^^^^^^^^^^^^^^^^^^^
  File "/home/runner/workspace/.pythonlibs/lib/python3.11/site-packages/flask/app.py", line 904, in finalize_request
    response = self.process_response(response)
               ^^^^^^^^^^^^^^^^^^^^^^^^^^^^^^^
  File "/home/runner/workspace/.pythonlibs/lib/python3.11/site-packages/flask/app.py", line 1284, in process_response
    self.session_interface.save_session(self, ctx.session, response)
  File "/home/runner/workspace/.pythonlibs/lib/python3.11/site-packages/flask_session/base.py", line 305, in save_session
    self._upsert_session(app.permanent_session_lifetime, session, store_id)
  File "/home/runner/workspace/.pythonlibs/lib/python3.11/site-packages/flask_session/redis/redis.py", line 81, in _upsert_session
    self.client.set(
  File "/home/runner/workspace/.pythonlibs/lib/python3.11/site-packages/redis/commands/core.py", line 2335, in set
    return self.execute_command("SET", *pieces, **options)
           ^^^^^^^^^^^^^^^^^^^^^^^^^^^^^^^^^^^^^^^^^^^^^^^
  File "/home/runner/workspace/.pythonlibs/lib/python3.11/site-packages/redis/client.py", line 559, in execute_command
    return self._execute_command(*args, **options)
           ^^^^^^^^^^^^^^^^^^^^^^^^^^^^^^^^^^^^^^^
  File "/home/runner/workspace/.pythonlibs/lib/python3.11/site-packages/redis/client.py", line 565, in _execute_command
    conn = self.connection or pool.get_connection(command_name, **options)
                              ^^^^^^^^^^^^^^^^^^^^^^^^^^^^^^^^^^^^^^^^^^^^
  File "/home/runner/workspace/.pythonlibs/lib/python3.11/site-packages/redis/connection.py", line 1422, in get_connection
    connection.connect()
  File "/home/runner/workspace/.pythonlibs/lib/python3.11/site-packages/redis/connection.py", line 361, in connect
    raise TimeoutError("Timeout connecting to server")
redis.exceptions.TimeoutError: Timeout connecting to server